<?xml version="1.0"?>
<!-- LEKIWI Pan-Tilt Gimbal: 2-axis (yaw + pitch) with camera mount -->
<robot xmlns:xacro="http://www.ros.org/wiki/xacro">

  <xacro:macro name="lekiwi_gimbal" params="parent:=base_link prefix:=''">
    <!-- Pan (yaw) link -->
    <link name="${prefix}gimbal_yaw_link">
      <visual>
        <geometry>
          <cylinder radius="0.06" length="0.05"/>
        </geometry>
        <material name="silver">
          <color rgba="0.7 0.7 0.7 1.0"/>
        </material>
      </visual>
      <inertial>
        <mass value="0.5"/>
        <inertia ixx="5e-4" iyy="5e-4" izz="1e-3" ixy="0" ixz="0" iyz="0"/>
      </inertial>
    </link>

    <joint name="${prefix}gimbal_yaw_joint" type="revolute">
      <parent link="${parent}"/>
      <child link="${prefix}gimbal_yaw_link"/>
      <origin xyz="0 0 0.12" rpy="0 0 0"/>
      <axis xyz="0 0 1"/>
      <limit effort="10" velocity="6.28" lower="-3.14" upper="3.14"/>
    </joint>

    <!-- Tilt (pitch) link -->
    <link name="${prefix}gimbal_pitch_link">
      <visual>
        <geometry>
          <box size="0.08 0.04 0.03"/>
        </geometry>
        <material name="silver"/>
      </visual>
      <inertial>
        <mass value="0.3"/>
        <inertia ixx="2e-4" iyy="2e-4" izz="1e-4" ixy="0" ixz="0" iyz="0"/>
      </inertial>
    </link>

    <joint name="${prefix}gimbal_pitch_joint" type="revolute">
      <parent link="${prefix}gimbal_yaw_link"/>
      <child link="${prefix}gimbal_pitch_link"/>
      <origin xyz="0 0 0.03" rpy="0 0 0"/>
      <axis xyz="0 1 0"/>
      <limit effort="5" velocity="3.14" lower="-1.57" upper="1.57"/>
    </joint>

    <!-- Camera link (mounted on pitch axis) -->
    <link name="${prefix}camera_link">
      <visual>
        <geometry>
          <box size="0.04 0.02 0.02"/>
        </geometry>
        <material name="blue">
          <color rgba="0.1 0.1 0.8 1.0"/>
        </material>
      </visual>
      <inertial>
        <mass value="0.1"/>
        <inertia ixx="1e-5" iyy="1e-5" izz="1e-5" ixy="0" ixz="0" iyz="0"/>
      </inertial>
    </link>

    <joint name="${prefix}camera_joint" type="fixed">
      <parent link="${prefix}gimbal_pitch_link"/>
      <child link="${prefix}camera_link"/>
      <origin xyz="0.03 0 0" rpy="0 0 0"/>
    </joint>

    <!-- Camera optical frame (ROS convention: z-forward, x-right, y-down) -->
    <link name="${prefix}camera_optical_link"/>
    <joint name="${prefix}camera_optical_joint" type="fixed">
      <parent link="${prefix}camera_link"/>
      <child link="${prefix}camera_optical_link"/>
      <origin xyz="0 0 0" rpy="${-pi/2} 0 ${-pi/2}"/>
    </joint>

  </xacro:macro>
</robot>
